Traceback (most recent call last):
  File "C:\Users\richa\AppData\Roaming\Python\Python311\site-packages\jupyter_cache\executors\utils.py", line 58, in single_nb_execution
    executenb(
  File "C:\ProgramData\anaconda3\Lib\site-packages\nbclient\client.py", line 1204, in execute
    return NotebookClient(nb=nb, resources=resources, km=km, **kwargs).execute()
           ^^^^^^^^^^^^^^^^^^^^^^^^^^^^^^^^^^^^^^^^^^^^^^^^^^^^^^^^^^^^^^^^^^^^^
  File "C:\ProgramData\anaconda3\Lib\site-packages\nbclient\util.py", line 84, in wrapped
    return just_run(coro(*args, **kwargs))
           ^^^^^^^^^^^^^^^^^^^^^^^^^^^^^^^
  File "C:\ProgramData\anaconda3\Lib\site-packages\nbclient\util.py", line 62, in just_run
    return loop.run_until_complete(coro)
           ^^^^^^^^^^^^^^^^^^^^^^^^^^^^^
  File "C:\ProgramData\anaconda3\Lib\asyncio\base_events.py", line 653, in run_until_complete
    return future.result()
           ^^^^^^^^^^^^^^^
  File "C:\ProgramData\anaconda3\Lib\site-packages\nbclient\client.py", line 663, in async_execute
    await self.async_execute_cell(
  File "C:\ProgramData\anaconda3\Lib\site-packages\nbclient\client.py", line 965, in async_execute_cell
    await self._check_raise_for_error(cell, cell_index, exec_reply)
  File "C:\ProgramData\anaconda3\Lib\site-packages\nbclient\client.py", line 862, in _check_raise_for_error
    raise CellExecutionError.from_cell_and_msg(cell, exec_reply_content)
nbclient.exceptions.CellExecutionError: An error occurred while executing the following cell:
------------------
## Saturated Pressures using Antoine Equation

Psat_tol_mmHg = 10**(A_tol - B_tol/(T+C_tol)) ## mmHg
Psat_tol = Psat_tol_mmHg/760 ## atm

Psat_va_mmHg = 10**(A_va - B_va/(T+C_va)) ## mmHg
Psat_va = Psat_va_mmHg/760 ## atm

## Ki = Psat/P

K1 = Psat_tol/P ## unitless
K2 = Psat_va/P ## unitless

## F

F_tol = z_tol * Basis ## kmol/hr
F_va = z_va * Basis ## kmol/hr
------------------

[1;31m---------------------------------------------------------------------------[0m
[1;31mNameError[0m                                 Traceback (most recent call last)
Cell [1;32mIn[3], line 16[0m
[0;32m     12[0m K2 [38;5;241m=[39m Psat_va[38;5;241m/[39mP [38;5;66;03m## unitless[39;00m
[0;32m     14[0m [38;5;66;03m## F[39;00m
[1;32m---> 16[0m F_tol [38;5;241m=[39m z_tol [38;5;241m*[39m Basis [38;5;66;03m## kmol/hr[39;00m
[0;32m     17[0m F_va [38;5;241m=[39m z_va [38;5;241m*[39m Basis

[1;31mNameError[0m: name 'z_tol' is not defined
NameError: name 'z_tol' is not defined

